Workbook

Sheet Zdroj
B1: STOCK | C1: cars | D1: managers
A2: CZ | B2: PRAHA region | C2: 1896 | D2: =VLOOKUP(B2,$M$3:$S$83,2,"nepravda") -> Petr Neckař | R2: Obsazení poboček platné od | U2: 44197
B3: PRAHA ČESTLICE | C3: 177 | D3: =VLOOKUP(B3,$M$3:$S$83,2,"nepravda") -> Pavel Saidl
B4: ÚSTÍ NAD LABEM | C4: 148 | D4: =VLOOKUP(B4,$M$3:$S$83,2,"nepravda") -> Petr Janatka | M4: Country Sales Mng. CZ | N4: Miroslav Vápeník | X4: Country Manager | Z4: Milan Dědeček | AA4: Martin Roudnický | AB4: Josef Borovec | AC4: Jan Sokola
B5: PARDUBICE | C5: 206 | D5: =VLOOKUP(B5,$M$3:$S$83,2,"nepravda") -> Roman Debkowski | N5: Site Mng. | O5: Site Mng. | P5: Site Mng. | Q5: Replace Mng. | R5: Replace Mng. | S5: Sales Closing Mng. | T5: Sales Closing Mng. | U5: Sales Closing Mng. | V5: Sales Closing Mng. | W5: Sales Closing Mng. | X5: CAP | Y5: Training | Z5: F&I Regional Mng. | AA5: Buying Regional Mng. | AB5: Stock Regional Mng. | AC5: OPS Regional Mng.
B6: ČESKÉ BUDĚJOVICE | C6: 175 | D6: =VLOOKUP(B6,$M$3:$S$83,2,"nepravda") -> Marcel Majdak | M6: PRAHA region | N6: Petr Neckař | O6: Jan Kryl | AC6: Senior Teameleader
B7: TEPLICE | C7: 143 | D7: =VLOOKUP(B7,$M$3:$S$83,2,"nepravda") -> Jan Marek | M7: Praha | N7: Jiří Hromádka | O7: Dragan Ravič | Q7: David Teplý | R7: Jakub Vavřička | S7: Richard Junger | T7: Ivan Petřík | U7: Marek Kejla | V7: Pavel Škabraha | X7: 8 | Z7: Lukáš Bělohoubek | AA7: Martin Roudnický | AB7: Martin Cmíral | AC7: Jan Malchar
B8: CHOMUTOV | C8: 187 | D8: =VLOOKUP(B8,$M$3:$S$83,2,"nepravda") -> Jan Krušina | M8: Praha Čestlice | N8: Pavel Saidl | Q8: Michal Bouček | X8: 2 | Y8: Ondřej Fencl | Z8: Lukáš Bělohoubek | AA8: Martin Roudnický | AB8: Martin Cmíral | AC8: Jan Malchar
M9: BOHEMIA 1 | N9: Miroslav Varmuža
B10: HRADEC KRÁLOVÉ | C10: 226 | D10: =VLOOKUP(B10,$M$3:$S$83,2,"nepravda") -> Martin Leš | M10: České Budějovice | N10: Marcel Majdak | Q10: Tomáš Vybíral | S10: Aleš Goszler | X10: 2 | Z10: Tomáš Vaska | AA10: Marcel Ronge | AB10: Jan Zavřel | AC10: Roman Nekola
B11: KOLÍN | C11: 145 | D11: =VLOOKUP(B11,$M$3:$S$83,2,"nepravda") -> Jiří Vojáček | M11: Chomutov | N11: Jan Krušina | Q11: Lukáš Hromádko | X11: 2 | Z11: Tomáš Vaska | AA11: Lukáš Geršic | AB11: Stanislav Bernášek | AC11: Martin Čížek
B12: JIHLAVA | C12: 156 | D12: =VLOOKUP(B12,$M$3:$S$83,2,"nepravda") -> Lukáš Prokip | M12: Kladno | N12: Ondřej Michl | Q12: Jaroslav Kříž | X12: 2 | Z12: Tomáš Vaska | AA12: Lukáš Geršic | AB12: Martin Cmíral | AC12: Martin Čížek
B13: KLADNO | C13: 188 | D13: =VLOOKUP(B13,$M$3:$S$83,2,"nepravda") -> Ondřej Michl | M13: Plzeň | N13: Jan Chadt | Q13: Stanislav Šmerda | S13: Milan Kysilka | T13: Marek Černý | X13: 4 | Z13: Tomáš Vaska | AA13: Lukáš Geršic | AB13: Martin Cmíral | AC13: Martin Čížek
B14: PLZEŇ | C14: 335 | D14: =VLOOKUP(B14,$M$3:$S$83,2,"nepravda") -> Jan Chadt | M14: Sokolov | N14: Tomáš Mrňák | Q14: Jan Kříž | X14: 2 | Z14: Tomáš Vaska | AA14: Lukáš Geršic | AB14: Stanislav Bernášek | AC14: Martin Čížek
B15: LIBEREC | C15: 291 | D15: =VLOOKUP(B15,$M$3:$S$83,2,"nepravda") -> Milan Hozák | M15: Tábor | N15: Jan Brom | Q15: David Zika | X15: 2 | Z15: Tomáš Vaska | AA15: Marcel Ronge | AB15: Jan Zavřel | AC15: Roman Nekola
B16: SOKOLOV | C16: 182 | D16: =VLOOKUP(B16,$M$3:$S$83,2,"nepravda") -> Tomáš Mrňák | M16: BOHEMIA 2 | N16: Petr Kalabis
B17: BRNO | C17: 620 | D17: =VLOOKUP(B17,$M$3:$S$83,2,"nepravda") -> Radovan Kejík | M17: Hradec Králové | N17: Martin Leš | Q17: Lukáš Uhlíř | S17: Jiří Borovička | X17: 3 | Z17: Martin Kotlán | AA17: Marcel Ronge | AB17: Jan Zavřel | AC17: Roman Nekola
B18: OTROKOVICE | C18: 219 | D18: =VLOOKUP(B18,$M$3:$S$83,2,"nepravda") -> Ondřej Polák | M18: Kolín | N18: Jiří Vojáček | Q18: Marek Bucko | X18: 2 | Z18: Martin Kotlán | AA18: Marcel Ronge | AB18: Jan Zavřel | AC18: Roman Nekola
B19: OLOMOUC | C19: 304 | D19: =VLOOKUP(B19,$M$3:$S$83,2,"nepravda") -> Tomáš Krmela | M19: Liberec | N19: Milan Hozák | Q19: David Chott | S19: Roman Martinkovič | X19: 3 | Z19: Martin Kotlán | AA19: Marcel Ronge | AB19: Stanislav Bernášek | AC19: Martin Čížek
B20: OSTRAVA | C20: 461 | D20: =VLOOKUP(B20,$M$3:$S$83,2,"nepravda") -> Marián Kozák | M20: Mladá Boleslav | N20: Petr Šulc | Q20: Matěj Šorejs | X20: 2 | Z20: Martin Kotlán | AA20: Lukáš Geršic | AB20: Stanislav Bernášek | AC20: Roman Nekola
B21: OPAVA | C21: 125 | D21: =VLOOKUP(B21,$M$3:$S$83,2,"nepravda") -> Pavel Baitl | M21: Teplice | N21: Jan Marek | Q21: Ondřej Housa | X21: 2 | Z21: Martin Kotlán | AA21: Lukáš Geršic | AB21: Stanislav Bernášek | AC21: Martin Čížek
B22: TÁBOR | C22: 92 | D22: =VLOOKUP(B22,$M$3:$S$83,2,"nepravda") -> Jan Brom | M22: Ústí nad Labem | N22: Petr Janatka | Q22: Martin Janovský | S22: Ondřej Fencl | X22: 2 | Z22: Martin Kotlán | AA22: Lukáš Geršic | AB22: Stanislav Bernášek | AC22: Martin Čížek
B23: MLADÁ BOLESLAV | C23: 149 | D23: =VLOOKUP(B23,$M$3:$S$83,2,"nepravda") -> Petr Šulc | M23: MORAVIA 1 | N23: Jiří Pokorák
B24: ZNOJMO | C24: 105 | D24: =VLOOKUP(B24,$M$3:$S$83,2,"nepravda") -> Daniel Kudr | M24: Brno | N24: Radovan Kejík | O24: Alen Svoboda | Q24: Ondřej Ištván | R24: Martin Medek | S24: Vlastimil Košťál | X24: 6 | Z24: Martin Havel | AA24: Martin Kostelka | AB24: Michal Hroch | AC24: Jan Sokola
A25: SK | B25: BRATISLAVA | C25: 452 | D25: =VLOOKUP(B25,$M$3:$S$83,2,"nepravda") -> Lukáš Špak | M25: Jihlava | N25: Lukáš Prokip | Q25: Jiří Honek | X25: 2 | Z25: Martin Havel | AA25: Marcel Ronge | AB25: Stanislav Bernášek | AC25: Roman Nekola
B26: KOŠICE | C26: 237 | D26: =VLOOKUP(B26,$M$3:$S$83,2,"nepravda") -> Lukáš Bodorík | M26: Olomouc | N26: Tomáš Krmela | Q26: Jiří Peška | S26: Kamil Martínek | T26: Jan Čechák | X26: 4 | Z26: Martin Havel | AA26: Martin Kostelka | AB26: Michal Hroch | AC26: Jan Sokola
B27: ŽILINA | C27: 171 | D27: =VLOOKUP(B27,$M$3:$S$83,2,"nepravda") -> Marek Bartík | M27: Znojmo | N27: Daniel Kudr | Q27: Josef Šimůnek | X27: 2 | Z27: Martin Havel | AA27: Martin Kostelka | AB27: Michal Hroch | AC27: Jan Sokola
B28: NITRA | C28: 169 | D28: =VLOOKUP(B28,$M$3:$S$83,2,"nepravda") -> Libor Dvořák | M28: MORAVIA 2 | N28: Jiří Vávra
B29: BÁNSKÁ BYSTRICA | C29: 172 | D29: =VLOOKUP(B29,$M$3:$S$83,2,"nepravda") -> #N/A | M29: Opava | N29: Pavel Baitl | Q29: Tomáš Hadaščok | X29: 2 | Z29: Roman Chrástecký | AA29: Martin Kostelka | AB29: Michal Hroch | AC29: Jan Sokola
B30: TRENČÍN | C30: 178 | D30: =VLOOKUP(B30,$M$3:$S$83,2,"nepravda") -> Radoslav Skaloš | M30: Ostrava | N30: Marián Kozák | O30: Miroslav Petr | Q30: Jiří Kubínek | S30: Josef Wróbel | X30: 4 | Z30: Roman Chrástecký | AA30: Martin Kostelka | AB30: Michal Hroch | AC30: Jan Sokola
B31: MICHALOVCE | C31: 100 | D31: =VLOOKUP(B31,$M$3:$S$83,2,"nepravda") -> Michal Gluchman | M31: Pardubice | N31: Roman Debkowski | Q31: Tomáš Vančura | X31: 2 | Z31: Roman Chrástecký | AA31: Marcel Ronge | AB31: Jan Zavřel | AC31: Roman Nekola
B32: POPRAD | C32: 165 | D32: =VLOOKUP(B32,$M$3:$S$83,2,"nepravda") -> Pavol Chmura | M32: Otrokovice | N32: Ondřej Polák | Q32: Tomáš Hurník | S32: Vojtěch Žák | X32: 3 | Z32: Roman Chrástecký | AA32: Martin Kostelka | AB32: Michal Hroch | AC32: Jan Sokola
B33: LUČENEC | C33: 75 | D33: =VLOOKUP(B33,$M$3:$S$83,2,"nepravda") -> Lorant Magyar | M33: Country Sales Mng. SK | N33: Igor Suchý | X33: =SUM(X7:X32) -> 63 | Z33: Lukáš Faltus | AA33: Robert Wiedner | AB33: Bronislav Kroneisl
B34: NOVÉ ZÁMKY | C34: 93 | D34: =VLOOKUP(B34,$M$3:$S$83,2,"nepravda") -> #N/A | M34: BRATISLAVA region | N34: Marek Koláček
B35: PREŠOV | C35: 172 | D35: =VLOOKUP(B35,$M$3:$S$83,2,"nepravda") -> Martin Bibko | M35: Bratislava | N35: Lukáš Špak | O35: Ľuboš Vajnagi | Q35: Štefan Stronga | Z35: Mário Záborský | AA35: Erik Droppan | AB35: Tomáš Tulej | AC35: Michal Ledvenyi
B36: MARTIN | C36: 0 | D36: =VLOOKUP(B36,$M$3:$S$83,2,"nepravda") -> #N/A | M36: Trnava | N36: Jan Tichý | Q36: Lubo Šmondrk | Z36: Martin Bulíček | AA36: Erik Droppan | AB36: Tomáš Tulej | AC36: Juraj Chrást
B37: Liptovský Mikuláš | C37: 0 | D37: =VLOOKUP(B37,$M$3:$S$83,2,"nepravda") -> #N/A | M37: SLOVAKIA 1 | N37: Lukáš Svačina
B38: TRNAVA | C38: 161 | D38: =VLOOKUP(B38,$M$3:$S$83,2,"nepravda") -> Jan Tichý | M38: Nitra | N38: Libor Dvořák | Q38: Tomáš Pytel | R38: Matěj Gál | Z38: Martin Bulíček | AA38: Erik Droppan | AB38: Tomáš Tulej | AC38: Juraj Chrást
A39: HU | B39: Budapešť | C39: 32 | D39: =VLOOKUP(B39,$M$3:$S$83,2,"nepravda") -> #N/A | M39: Trenčín | N39: Radoslav Skaloš | Q39: Richard Lehotský | Z39: Martin Bulíček | AA39: Erik Droppan | AB39: Tomáš Tulej | AC39: Juraj Chrást
A40: PL | B40: Warsaw | C40: 669 | D40: =VLOOKUP(B40,$M$3:$S$83,2,"nepravda") -> Piotr Aszychmin | M40: Žilina | N40: Marek Bartík | Q40: Roman Janoš | Z40: Martin Bulíček | AA40: Erik Droppan | AB40: Tomáš Tulej | AC40: Juraj Chrást
...

Sheet   VACANCIES
A1: Status | B1: Date of openning | C1: Time to hired | D1: Request for position | E1: Division | F1: Department | G1: Position | H1: Salary | I1: Hiring Manager | J1: Generalist | K1: Sources | L1: Comments | M1: No of CVs TOTAL | N1: CAP | O1: ACTUAL | P1: VAC
B2: TOTAL: PRAGUE HQ / BO + BRANCHES | N2: =SUM($N$3:$N$4) -> #REF! | O2: =SUM($O$3:$O$4) -> #REF! | P2: =SUM($P$3:$P$4) -> #REF!
N3: =SUM(#REF!,N50,N34) -> #REF! | O3: =SUM(#REF!,O50,O34) -> #REF! | P3: =SUM(#REF!,P50,P34,P43) -> #REF!
B4: PRAGUE HQ / BO | N4: =SUM(N5:N27) -> 195.63 | O4: =SUM(O5:O27) -> 171.14 | P4: =SUM(P5:P29) -> 37
A5: RPL (fill cap) | B5: 45782 | C5: =_xlfn.DAYS(TODAY(),B5) -> 303 | D5: 169094, 169093, 169092, | E5: 11_Call Centre | F5: CC_Ostrava | G5: CC Representative | H5: 21 000 + 0- 9 000 (1.+2.měsíc) 21 000 + %(od 3.měs.) | I5: Jan Kovář | J5: Anna K. | K5: AAA, dobra práce, práce.cz, Inwork | L5: Last hir: Blahutová, Marcol, Demeterová, Pochmanová(2.6.) No after 2nd: Marcolová (20. 3.) Kniezková (7.4.) no after 2nd: Hráčková, Jurásková, Vagáiová, | M5: 150 | N5: 51.63 | O5: 44.38 | P5: 7
A6: RPL (fill cap) | B6: 45810 | C6: =_xlfn.DAYS(TODAY(),B6) -> 275 | D6: 170489, 170490, 170491,170492, 170493 | E6: 11_Call Centre | F6: CC_Praha | G6: CC Representative | H6: 22 000 + 0- 13 000 (1.+2.měsíc) 22 000 + %(od 3.měs.) | I6: Vojta Toráč | J6: Kamila | K6: AAA, dobra práce, práce.cz, Inwork, FR | L6: Hired: Maternová, Hubačová, Vojtela ,Hiring: Nováková (1.7.), Mačáková, Šolcová (?), Bino (1.8.) no after 2nd: Křížová, Šimůnková, Švec, Bologa Didn´t come: Shonová, Tulej Refused offer: Bartáková, Skalová | M6: 68 | N6: 45 | O6: 38.76 | P6: 5 | Q6: Martin Tampír
A7: RPL (Hartlová) | B7: 45805 | C7: =_xlfn.DAYS(TODAY(),B7) -> 280 | D7: 169911 | E7: 21_Commerce | F7: Import & Export | G7: Assistant | H7: 25.000 + 0 - 25.000 KPI | I7: Robert Radler | J7: Ondra | K7: AAA, práce | L7: Hired Kmochová For 2nd Krásnová, Havlíčková | M7: 11 | N7: 4 | O7: 4 | P7: 1
A8: RPL (Gamazova) | B8: 45786 | C8: =_xlfn.DAYS(TODAY(),B8) -> 299 | D8: 168637 | E8: 01_Marketing & Communication | F8: Web and Direct Marketing | G8: Web Specialist | H8: negotiable | I8: Martin Tampír | J8: Ondra | K8: AAA, jobs, LI, Profesia | L8: In considering Suská No after phonescreen 4x Checking CVs | M8: 5 | N8: 2 | O8: 2 | P8: 1
A9: RPL (Polcar) | B9: 45789 | C9: =_xlfn.DAYS(TODAY(),B9) -> 296 | D9: 168789 | E9: 01_Marketing & Communication | F9: Digital Marketing | G9: Online Marketing Specialist | H9: negotiable | I9: Karel Smrž | J9: Anička | K9: AAA, jobs, práce.cz, LI | L9: Checking CV's No after 2nd Šuťák | M9: 5 | N9: 1 | O9: 1 | P9: 1
A10: RPL (Šubrt) + NEW | B10: 45789 | C10: =_xlfn.DAYS(TODAY(),B10) -> 296 | D10: 168935 | E10: 01_Marketing & Communication | F10: Brand Design | G10: Graphic | H10: negotiable | I10: Karel Smrž | J10: Anička | K10: AAA, jobs, práce.cz, LI | L10: Hiring Vašíčková, Procházka (16.6) Got offer for external cooperation Melanikova Case study Střelec, Svoboda, Mihal No after 2nd Ranc, Gabriel, Tvrz, Povolný, Brna, Baldina, Gobunov, Pícha | M10: 0 | N10: 2 | O10: 2 | P10: 2
A11: NEW CAP | B11: 45818 | C11: =_xlfn.DAYS(TODAY(),B11) -> 267 | D11: Waiting for RFP | E11: 01_Marketing & Communication | F11: Brand Design | G11: DTP/Graphic | H11: negotiable | I11: Jan Metelka | J11: Anička | K11: AAA, jobs, práce.cz, LI | L11: New request | M11: 0 | N11: 1 | O11: 1 | P11: 1
A12: RPL (Kappel) | B12: 45751 | C12: =_xlfn.DAYS(TODAY(),B12) -> 334 | D12: 170526 | E12: 04_Economic | F12: Consolidation & Projects | G12: Group Tax Manager | H12: negotiable | I12: Vojtěch Karban | J12: Anička | K12: AAA, jobs, LI, FR | L12: Msg sent 25x Refused practice test Malina Not responding Skalický No after psc Hýža | M12: 3 | N12: 1 | O12: 1 | P12: 1
A13: RPL (Kočová) | B13: 45784 | C13: =_xlfn.DAYS(TODAY(),B13) -> 301 | D13: 168872 | E13: 04_Economic | F13: Consolidation & Projects | G13: IFRS Specialist | H13: negotiable | I13: Martin Přibyl | J13: Anička | K13: AAA, jobs, LI, FR | L13: For 2nd Papanov (4.6) Good for psc Němeček Not interested Beránková Overpriced Ustianskyi | M13: 2 | N13: 2 | O13: 2 | P13: 1
A14: RPL (Kralovičová) | B14: 45720 | C14: =_xlfn.DAYS(TODAY(),B14) -> 365 | D14: 165269 | E14: 06_HR | F14: Personnel&Payroll | G14: Payroll Accountant | H14: negotiable | I14: Jitka Hořejší | J14: Ondra | K14: AAA, Jobs, intersource, ATS search | L14: Hired 23.6. Havelková | M14: 6 | N14: 4 | O14: 4 | P14: 1
A15: RPL (Jurštak) | B15: 45796 | C15: =_xlfn.DAYS(TODAY(),B15) -> 289 | D15: 168877 | E15: 06_HR | F15: Personnel&Payroll | G15: HR Controller | H15: negotiable Ref. | I15: Martina Kahulová | J15: Vlaďka | K15: intersource, ATS search | L15: got offer Zajícová, after 1 st internal candidate | M15: 2 | N15: 1 | O15: 1 | P15: 1
A16: RPL (Vojtíšek) | B16: 45757 | C16: =_xlfn.DAYS(TODAY(),B16) -> 328 | D16: 167036 | E16: 12_IT | F16: IT Development | G16: Project Manger | H16: negotiable | I16: Robert Šmol | J16: Ondra | K16: AAA, jobs, LI | L16: Hiring Havrylova | M16: 2 | N16: 1 | O16: 1 | P16: 1
A17: RPL (Jurčík) | B17: 45733 | C17: =_xlfn.DAYS(TODAY(),B17) -> 352 | D17: 154897 | E17: 08_Service | F17: Service | G17: Mechanic / Brno | H17: negotiable Ref. Náb.příspěvek | I17: Miroslav Knap | J17: Honza | K17: AAA, jobdnes, volnamista,facebook, dobrá práce, práce cz,inwork | L17: Checking CVs Hired Kosek (17.3.), Plaček (4.3.) Refused offer Brezánsky No after 1st Huspenina, Sokol, Kopecký, Hošek (not suitable), Lavička, Čamek (didnt start), Šlehofer (didnt come) | M17: 16 | N17: 8 | O17: 7 | P17: 1
A18: RPL (Válek) | B18: 45733 | C18: =_xlfn.DAYS(TODAY(),B18) -> 352 | D18: 140136 | E18: 08_Service | F18: Service | G18: Mechanic / Praha | H18: negotiable Ref. | I18: Miroslav Knap | J18: Honza | K18: AAA, jobdnes, volnamista,facebook, dobrá práce, práce cz,inwork | L18: Checking CVs | M18: 5 | N18: 22 | O18: 21 | P18: 1
A19: RPL (Hlavatý) | B19: 45803 | C19: =_xlfn.DAYS(TODAY(),B19) -> 282 | D19: 169604 | E19: 08_Service | F19: Service | G19: Mechanic / Hradec Králové | H19: negotiable Ref. | I19: Miroslav Knap | J19: Honza | K19: AAA, jobdnes, volnamista,facebook, dobrá práce, práce cz,inwork | L19: New request | M19: 1 | N19: 2 | O19: 2 | P19: 1
A20: RPL (Beck) | B20: 45817 | C20: =_xlfn.DAYS(TODAY(),B20) -> 268 | D20: 170522 | E20: 08_Service | F20: Warehouse | G20: Tires Storeman | H20: 30.000 + 0 - 10.000 VB | I20: Luboš Štangler | J20: Honza | K20: AAA, jobdnes, dobrá práce, práce cz,inwork | L20: New request | M20: 0 | N20: 3 | O20: 2 | P20: 1
A21: RPL (fill cap) | B21: 45800 | C21: =_xlfn.DAYS(TODAY(),B21) -> 285 | D21: 169630 | E21: 08_Service | F21: Service | G21: Smart Repair Technician - AVIA | H21: 26 000+ 0-14 000 VB | I21: Petr Šimeček/Miloš Ponáhlý | J21: Mirka | K21: AAA, jobdnes, volnamista, dobrá práce, práce cz,inwork | L21: Hiring: Vejvoda (LP) | M21: 0 | N21: 1 | O21: 0 | P21: 1
A22: RPL (fill cap) | B22: 45586 | C22: =_xlfn.DAYS(TODAY(),B22) -> 499 | D22: 154898 | E22: 08_Service | F22: Service | G22: Panel Beater | H22: negotiable | I22: Miroslav Knap | J22: Honza | K22: AAA, práce.cz, pracezarohem, dobraprace | L22: Checking CVs | M22: 0 | N22: 2 | O22: 0 | P22: 1
A23: NEW CAP | B23: 45755 | C23: =_xlfn.DAYS(TODAY(),B23) -> 330 | D23: 167206 | E23: 07_Stock & Logistics | F23: Stock | G23: Stock Controller - Znojmo | H23: 25 000 + 0- 25 000 VB | I23: Borovec Josef | J23: Blanka | K23: AAA, práce.cz, pracezarohem, dobraprace | L23: Hiring Tihlařík (1.7.) Checking CV | M23: 6 | N23: 1 | O23: 0 | P23: 1
A24: RPL Hánová | B24: 45783 | C24: =_xlfn.DAYS(TODAY(),B24) -> 302 | D24: 168833 | E24: 07_Stock & Logistics | F24: Stock | G24: Courier DPP - Otrokovice | H24: 125,-Kč/hod. | I24: Borovec Josef/Michal Hroch | J24: Mirka | K24: AAA, práce.cz, pracezarohem, dobraprace | L24: Checking CVs | M24: 1 | N24: 1 | O24: 0 | P24: 1
A25: RPL (Macháčková) | B25: 45797 | C25: =_xlfn.DAYS(TODAY(),B25) -> 288 | D25: waiting for | E25: 07_Stock & Logistics | F25: Stock | G25: Courier DPP - České Budějovice | H25: 125,-Kč/hod. | I25: Borovec Josef | J25: Mirka | K25: AAA, práce cz., pracezarohem, dobraprace, jobdnes | L25: For 1st: Maxová, Tuma (5.6) | M25: 6 | N25: 1 | O25: 1 | P25: 1
A26: RPL (Soukup) | B26: 45796 | C26: =_xlfn.DAYS(TODAY(),B26) -> 289 | D26: 169251 | E26: 02_Car Sales | F26: Customer Care | G26: Customer Care Technician - Praha | H26: 35 000 + 0-11 000 KPI | I26: Žerebný Michal | J26: Blanka | K26: AAA, práce.cz, pracezarohem, dobraprace, volnamista, jobdnes | L26: For 2nd Pudil, Reil (13.6.) Checking CV | M26: 4 | N26: 3 | O26: 2 | P26: 1
A27: RPL (Müller, Šimek, Sedláček) | B27: 45782 | C27: =_xlfn.DAYS(TODAY(),B27) -> 303 | D27: 168761 154646 | E27: 05_Car Purchase | F27: Pricing | G27: Pricing Expert | H27: 30 000 + 0 - 10 000 VB (GB 3m) | I27: Jiří Somol | J27: Anna K. | K27: AAA, práce.cz, jobs.cz, dobraprace, volnamista, jobdnes | L27: Hiring: Vitouš (1.8.) Last h: Tejnický (2. 6.),, Griessl (5.5.), Osagiede (1. 4.), Rudiš (3.3.) | M27: 19 | N27: 36 | O27: 34 | P27: 1
A28: RPL (fill cap) | B28: 45761 | C28: =_xlfn.DAYS(TODAY(),B28) -> 324 | D28: 170023 170515 | E28: 05_Car Purchase | F28: Mobile Buying | G28: Mobile Buyer - Praha | H28: 25000+VB | I28: Tomáš Kaprálek | J28: Mirka | K28: AAA, práce.cz, pracezarohem, dobraprace | L28: For 1st: Beránek (4.6), Srna (11.6) Hiring: Koc (14.4) Not suitable: Hořínek | M28: 30 | N28: 8 | O28: 7 | P28: 2
A29: RPL (fill cap) | B29: 45775 | C29: =_xlfn.DAYS(TODAY(),B29) -> 310 | D29: 170015 | E29: 05_Car Purchase | F29: Mobile Buying | G29: Mobile Buyer - Otrokovice | H29: 25000+VB | I29: Tomáš Kaprálek | J29: Mirka | K29: AAA, práce.cz, pracezarohem, dobraprace | L29: nev request | M29: 0 | N29: 1 | O29: 1 | P29: 1
B30: MOTOTECHNA | L30: ) | N30: =SUM(N31:N33) -> 4 | O30: =SUM(O31:O33) -> 4 | P30: =SUM(P31:P33) -> 3
A31: RPL (Todorov) | B31: 45775 | C31: =_xlfn.DAYS(TODAY(),B31) -> 310 | D31: Waiting for RFP | E31: 16_Mototechna | F31: Mototechna Drive | G31: Operations Manager | H31: Negotiable | I31: Jan Hrubý | J31: Anna K. | K31: AAApráce, jobs | L31: For 2nd: Čori, Jonáš No: Mayrichová, Sattler, Zuber | M31: 7 | N31: 1 | O31: 1 | P31: 1
A32: RPL (Flek) | B32: 45790 | C32: =_xlfn.DAYS(TODAY(),B32) -> 295 | D32: 170028 | E32: 16_Mototechna | F32: Mototechna 2.0 | G32: Car Trader | H32: negotiable | I32: Jan Hrubý | J32: Anna K. | K32: AAApráce, jobs | L32: NO: Ben Nasim, Novák, Palokaj | N32: 3 | O32: 2 | P32: 1
A33: NEW | B33: 45782 | C33: =_xlfn.DAYS(TODAY(),B33) -> 303 | D33: DPP | E33: 16_Mototechna | F33: Mototechna 2.0 | G33: Driver_Mototechna 2.0 | H33: 150 Kč/hod | I33: Michal Kučera | J33: Anna K. | K33: AAA | L33: Hiring: Foldin (dle LP červen), Omluvil se z pohovoru: Sůva (19.5.) | M33: 5 | N33: 0 | O33: 1 | P33: 1
A34: Reg. Praha | B34: PRAGUE BRANCH | N34: =SUM(N35:N42) -> 138 | O34: =SUM(O35:O42) -> 130 | P34: =SUM(P35:P42) -> 16
A35: RPL (fill cap) | B35: 45792 | C35: =_xlfn.DAYS(TODAY(),B35) -> 293 | D35: 170558 170556 170555 | E35: 02_Car Sales | F35: Selling | G35: Salesman - Praha | H35: 22 000 / 25 000 + % NP 30 | I35: Petr Neckař | J35: Ondra | K35: AAA, práce.cz, jobs.cz, dobraprace, volnamista, jobdnes, FB | L35: Hired 1.7. Grayton, Olashy, Bílý, Kotouček, Dunda (1.8.) | M35: 58 | N35: 38.5 | O35: 37.5 | P35: 3
A36: RPL (Rybínová, Hudeková) | B36: 45758 | C36: =_xlfn.DAYS(TODAY(),B36) -> 327 | D36: 167171 168467 | E36: 02_Car Sales | F36: Selling | G36: Receptionist | H36: 22.000 + 0 - 10.000 | I36: Petr Neckař | J36: Ondra | K36: AAA, práce | L36: Hired 1.6. Kralertová (1/2), 1.7. Chlupáčová (1/2) | N36: 4.5 | O36: 5 | P36: 1
A37: RPL(Fill cap, Ravič) | B37: 45810 | C37: =_xlfn.DAYS(TODAY(),B37) -> 275 | D37: 165511 170511 | E37: 03_Financial Services | F37: Selling Support | G37: Customer Service Specialist - Praha | H37: 25.000 + % | I37: David Hlavnička/Tereza Holečková | J37: Mirka | K37: AAA, párce.cz, párce za rohem, jobs.cz | L37: Hired: Gallik (2.6) IM: Adamová Valerie No after PD: Kvasničková No after 1st.: Fialka, Rothanzl, Formanová (not suitable) Refused offer: Hrabarova, Valentová, Brabec | M37: 35 | N37: 28 | O37: 27.5 | P37: 2
A38: RPL (fill cap) | B38: 45742 | C38: =_xlfn.DAYS(TODAY(),B38) -> 343 | D38: 162756 167792 167799 | E38: 05_Car Purchase | F38: Buying | G38: Test Driver | H38: 22 000 + % | I38: Petr Kuchynka | J38: Blanka | K38: AAA, párce.cz, párce za rohem, | L38: Hiring Žilka (1.8.) For 2nd Bakalář (9.6.) No after 2nd Slabý, Vinklář, Tkadlec, Horvát, Bittner, Dupal Didnt come Kubánek, Rolenc, Moravec, Beneš Checking CV | M38: 16 | N38: 20 | O38: 16 | P38: 3
A39: RPL (fill cap) | B39: 45810 | C39: =_xlfn.DAYS(TODAY(),B39) -> 275 | D39: HPP | E39: 02_Car Sales | F39: Selling | G39: Assistant Salesman | H39: 25.000 + 15.000 | I39: Petr Neckař | J39: Ondra | K39: AAA, práce, jobs | L39: After 2nd Kovalenko Hired 2.6. Stehlík No after 2nd 2x | M39: 9 | N39: 12 | O39: 10 | P39: 2
A40: RPL (Kroc) | B40: 45799 | C40: =_xlfn.DAYS(TODAY(),B40) -> 286 | D40: 169572 | E40: 04_Automotive OPS | F40: OPS (Full Time) | G40: Helper_Boxy | H40: 26 000 + 0 - 8000 | I40: Jan Malchar | J40: Anna K. | K40: AAA | L40: Hiring: Gomba Jan (dle lp červen) | M40: 1 | N40: 6 | O40: 6 | P40: 1
...

Sheet VAC_History
A1: Date | B1: Total VAC
A2: 45625 | B2: 70.75
A3: 45642 | B3: 66.25
A4: 45646 | B4: 67.25
A5: 45656 | B5: 67.25
A6: 45666 | B6: 59.25
A7: 45674 | B7: 76.5
A8: 45681 | B8: 78.5
A9: 45695 | B9: 112
A10: 45702 | B10: 119
A11: 45709 | B11: 121.25
A12: 45711 | B12: 121.25
A13: 45716 | B13: 128.75
... A58: 46084 | B58: 103

Sheet Podrobnosti1
A1: Podrobnosti pro Vacancies – Division: 05_Car Purchase
A3: Status | B3: Place | C3: Date of opening | D3: Time to fill | E3: Request for position | F3: Division | G3: Department | H3: Position | I3: Salary | J3: Hiring Manager | K3: Generalist | L3: Sources | M3: Comments | N3: CAP | O3: ACTUAL | P3: VAC
A4: NEW | B4: Jihlava (Třebíč) | C4: 45947 | D4: 28 | E4: 179003 | F4: 05_Car Purchase | G4: Buying | H4: Test driver - Jihlava (Třebíč) | I4: 22 000 + 0 - 18 000 | J4: Marcel Ronge | K4: Kája | L4: AAA, párce.cz, párce za rohem, jobdnes | M4: Refused offer: Kašpar, Hired: Svoboda (10.11.) For 2nd: Richtr, Kašpar, Láník (6.11.) Checking CVs | N4: 2 | O4: 0 | P4: 1
A5: NEW | B5: Brno | C5: 45947 | D5: 28 | E5: 179002 | F5: 05_Car Purchase | G5: Buying | H5: Test driver - Brno | I5: 22 000 + 0 - 18 000 | J5: Martin Kostelka | K5: Kamila | L5: AAA, prace.cz, pracezarohem, jobdnes | M5: To 2nd: Baláž (18.11.), to 2nd: Miksa, Žákovský (waiting for term) | N5: 10 | O5: 8 | P5: 3
A6: RPL (IM) | B6: ČESKÉ BUDĚJOVICE | C6: 45957 | D6: 18 | E6: 180119 | F6: 05_Car Purchase | G6: Buying | H6: Test driver - České Budějovice | I6: 22 000 + 0 - 18 000 | J6: Marcel Ronge | K6: Kája | L6: AAA, párce.cz, práce za rohem, jobdnes | M6: Checking CVs (IM - Jaroš, Ondrůšek) | N6: 5 | O6: 3 | P6: 1
A7: RPL (Kilián) | B7: Čestlice/Příbram | C7: 45971 | D7: 4 | E7: 179002 | F7: 05_Car Purchase | G7: Buying | H7: Test driver - Příbram | I7: 22 000 + 0 - 18 000 | J7: Lukáš Geršic | K7: Kamila | L7: AAA, prace.cz, pracezarohem, jobdnes | M7: new 1x IM (F.Hořínek ze Sokolova) | N7: 2 | O7: 0 | P7: 2
A8: RPL(fill cap) | B8: PRAGUE HQ / BO | C8: 45937 | D8: 38 | E8: 178528 | F8: 05_Car Purchase | G8: Mobile Buying | H8: Mobile Buying- České Budějovice | I8: 25000+% | J8: Tomáš Kaprálek | K8: Mirka | L8: AAA, práce.cz, jobs.cz, dobraprace, volnamista, jobdnes, pracezarohem | M8: Checking CVs No after 1st: Chlan | N8: 1 | O8: 1 | P8: 1
A9: (RPL Vargová - IM) | B9: PRAGUE HQ / BO | C9: 45959 | D9: 16 | E9: 179978 | F9: 05_Car Purchase | G9: Segment Buying | H9: Assistant | I9: negotiable | J9: Tomáš Preus | K9: Vlaďka | L9: Recommended | M9: rejected offer Videnková, After 1st
A10: RPL (Lukáš Vodák) | B10: PRAGUE HQ / BO | C10: 45931 | D10: 44 | E10: 180118 | F10: 05_Car Purchase | G10: Pricing | H10: Pricing Expert | I10: 30 000 + 0 - 10 000 VB (GB 3m) | J10: Jiří Somol | K10: Anna K. | L10: AAA, práce.cz, jobs.cz, dobraprace, volnamista, jobdnes | M10: For 2nd: Jungman (13.11.) Last h: Kříž Michal (1.10.), Dominik Burr (1.10.), Tejnický (2. 6.),Griessl (5.5.), Osagiede (1. 4.), Rudiš (3.3.) No after 2nd: Horák Ref.off: Vitouš | N10: 36 | O10: 35 | P10: 1

Sheet VACANCIES
A1: RPL / NEW | B1: Comment | C1: Place | D1: Date of opening | E1: Time to fill | F1: Request for position | G1: Division | H1: Department | I1: Position | J1: Salary | K1: Hiring Manager | L1: Generalist | M1: Sources | N1: Comments | O1: CAP | P1: ACTUAL | Q1: VAC
C2: Prague HQ / BO
A3: RPL | B3: fill cap | C3: Ostrava | D3: 46069 | E3: =_xlfn.DAYS(TODAY(),D3) -> 16 | G3: 11_Call Centre | H3: Call Centre | I3: CC Representative | J3: 22 500 + 0 - 7 500 (GB 1. a 2. měsíc, 3.+ %) | K3: Jan Kovář | L3: Anna K. | M3: AAA | N3: Hired: Bandurová, Jurek (16. 2.), Hiring: Horáková, Malíková (2.3.) No: Baláž | O3: 50.13 | P3: 45.1 | Q3: 5
A4: RPL | B4: Franková | C4: Prague HQ / BO | D4: 46069 | E4: =_xlfn.DAYS(TODAY(),D4) -> 16 | G4: 11_Call Centre | H4: Call Centre | I4: CC Representative | J4: 22 500 + 0 - 12 500 (1.+2. měsíc) 22 500 + % (od 3. měsíce) | K4: Vojta Toráč | L4: Kája | M4: AAA, práce za rohem, práce.cz | N4: Hired: Bino, Jusko (2.3.) Semecká- long term sickness | O4: 41 | P4: 42 | Q4: 0
A5: RPL | B5: Roubal | C5: Prague HQ / BO | D5: 46055 | E5: =_xlfn.DAYS(TODAY(),D5) -> 30 | F5: 182910 | G5: 08_Service | H5: Service | I5: Mechanic / Praha | J5: negotiable Ref. | K5: Miroslav Knap | L5: Honza | M5: AAA, jobdnes, dobrá práce, práce cz,inwork | N5: Checking CVs Hired Roubal (4.11.), Hensl (2.2.) | O5: 23 | P5: 21 | Q5: 2
A6: NEW | C6: Prague HQ / BO | D6: 45907 | E6: =_xlfn.DAYS(TODAY(),D6) -> 178 | F6: Waiting for RFP | G6: 08_Service | H6: Service | I6: Mechanic / České Budějovice | J6: negotiable Ref. | K6: Miroslav Knap | L6: Honza | M6: AAA, jobdnes, dobrá práce, práce cz,inwork | N6: IM Setikovský (1.3.) | O6: 2 | P6: 1 | Q6: 1
A7: RPL | B7: Daněk | C7: Brno | D7: 46076 | E7: =_xlfn.DAYS(TODAY(),D7) -> 9 | F7: 179250 | G7: 08_Service | H7: Service | I7: Mechanic / Brno | J7: negotiable Ref. | K7: Miroslav Knap | L7: Honza | M7: AAA, jobdnes, dobrá práce, práce cz,inwork | N7: new RQ | O7: 8 | P7: 7 | Q7: 1
A8: RPL | B8: Mikula | C8: Kladno | D8: 45956 | E8: =_xlfn.DAYS(TODAY(),D8) -> 129 | F8: 179250 | G8: 08_Service | H8: Service | I8: Mechanic / Kladno | J8: negotiable Ref. | K8: Miroslav Knap | L8: Honza | M8: AAA, jobdnes, dobrá práce, práce cz,inwork | N8: Checking CVs | O8: 1 | P8: 0 | Q8: 1
A9: RPL | B9: Kaštánek | C9: Prague HQ / BO | D9: 46038 | E9: =_xlfn.DAYS(TODAY(),D9) -> 47 | F9: Waiting for RFP | G9: 10_Office Operations | H9: Facility & Constuction | I9: Serviceman | J9: 30 000 + 0 - 8 000 KPI | K9: Petr Rinda | L9: Kamila | M9: Recommended | N9: hiring: Chalupecký (2.3.), refused offer: Babka | O9: 2 | P9: 2 | Q9: 1
A10: RPL | B10: Boušková | C10: Prague HQ / BO | D10: 46072 | E10: =_xlfn.DAYS(TODAY(),D10) -> 13 | F10: Waiting for RFP | G10: 10_Office Operations | H10: Warehouse & Archive | I10: Stockkeeper | J10: 30 000 + 0 - 9 000 KPI | K10: Ludvík Zawora | L10: Kamila | M10: AAA, práce cz, pracezarohem, inwork | N10: checking CVs | O10: 2 | P10: 2 | Q10: 1
A11: RPL | B11: Bartková/Varyš | C11: Prague HQ / BO | D11: 46072 | E11: =_xlfn.DAYS(TODAY(),D11) -> 13 | F11: Waiting for RFP | G11: 22_Cost Control & Back Office | H11: Cost Controlling & Procurement | I11: Procurement Specialist | J11: 43 000 + 0 - 10 000 KPI | K11: Michaela Kosinerová | L11: Kamila | M11: Recommended | N11: plánovaný IM | O11: 1.5 | P11: 0.5 | Q11: 1
A12: RPL | B12: fill cap, Šebánek, Černý | C12: Prague HQ / BO | D12: 46028 | E12: =_xlfn.DAYS(TODAY(),D12) -> 57 | F12: 176542 | G12: 07_Stock & Logistics | H12: Stock | I12: Stock Controller - Praha | J12: 25 000 + 0 - 25 000 KPI | K12: Borovec Josef | L12: Blanka | M12: AAA, práce.cz, pracezarohem, dobraprace | N12: Hiring Švarc After 2nd Butora, Cimburek No Afier 2nd Nouzák, Kolomazník Refused practise day Kulhánek Checking CV | O12: 7 | P12: 6 | Q12: 3
A13: RPL | B13: fill cap | C13: Liberec | D13: 46028 | E13: =_xlfn.DAYS(TODAY(),D13) -> 57 | F13: 176542 | G13: 07_Stock & Logistics | H13: Stock | I13: Stock Controller - Liberec | J13: 25 000 + 0 - 25 000 KPI | K13: Borovec Josef | L13: Blanka | M13: AAA, práce.cz, pracezarohem, dobraprace | N13: Hiring Saska (23.3.) No after 2nd Rejman Checking CV | O13: 2 | P13: 1 | Q13: 1
A14: RPL | B14: Setikovský | C14: Liberec | D14: 46049 | E14: =_xlfn.DAYS(TODAY(),D14) -> 36 | F14: 176542 | G14: 07_Stock & Logistics | H14: Stock | I14: Stock Controller - České Budějovice | J14: 25 000 + 0 - 25 000 KPI | K14: Borovec Josef | L14: Blanka | M14: AAA, práce.cz, pracezarohem, dobraprace | N14: Hiring Rotšédl (1.4.) No after 2nd Fomín Checking CVs | O14: 3 | P14: 3 | Q14: 1
A15: RPL | B15: fill cap | C15: Kladno | D15: 46077 | E15: =_xlfn.DAYS(TODAY(),D15) -> 8 | G15: 07_Stock & Logistics | H15: Stock | I15: Courier DPP - Kladno | J15: 140,-Kč//hod | K15: Jan Zvikl | L15: Mirka | M15: AAA, práce.cz, pracezarohem, dobraprace | N15: Checking CVs new request | O15: 0.25 | P15: 0 | Q15: 1
A16: RPL | B16: fill cap | C16: České Budějovice | D16: 46080 | E16: =_xlfn.DAYS(TODAY(),D16) -> 5 | G16: 07_Stock & Logistics | H16: Stock | I16: Courier DPP - České Budějovice | J16: 140,-Kč/hod. | K16: Jan Zvikl | L16: Mirka | M16: AAA, práce.cz, pracezarohem, dobraprace | N16: Checking CVs/new request | O16: 0.25 | P16: 0 | Q16: 1
A17: RPL | B17: Bryňák LTS, Kostiuk, Zlúky | C17: Prague HQ / BO | D17: 46084 | E17: =_xlfn.DAYS(TODAY(),D17) -> 1 | F17: 176542 | G17: 07_Stock & Logistics | H17: Logistics | I17: Tow Truck Driver - Praha | J17: 25 000 + 0 - 15 000 OSOH + 0 - 15 000 VB | K17: Alexandr Jordanov | L17: Mirka | M17: AAA, práce.cz, pracezarohem, dobraprace | N17: Hring: Hranáč (3.3) Hired: Zlúky (1.12)Ludvik(17.2) For 1st:Liška(19.2) For2nd: Hranáč(30.1) Refused offer:Jirovec, Brudny, Bartoň Dindnt comme: Macháček(13.10), Chromec | O17: 30 | P17: 30 | Q17: 2
A18: RPL | B18: Klejzar | C18: Prague HQ / BO | D18: 46048 | E18: =_xlfn.DAYS(TODAY(),D18) -> 37 | G18: 02_Car Sales | H18: Customer Care | I18: Customer Care Technician | J18: 35 000 + 0 - 11 000 KPI | K18: Žerebný Michal | L18: Blanka | M18: AAA, práce.cz, pracezarohem, dobraprace | N18: Hiring Vojta No after 2nd Mašek Checking CVs | O18: 3 | P18: 1.5 | Q18: 1
A19: RPL | C19: Prague HQ / BO | D19: 46028 | E19: =_xlfn.DAYS(TODAY(),D19) -> 57 | F19: 178528 | G19: 05_Car Purchase | H19: Mobile Buying | I19: Mobile Buying- Praha | J19: 25000+% | K19: Tomáš Kaprálek | L19: Mirka | M19: AAA, práce.cz, jobs.cz, dobraprace, volnamista, jobdnes, pracezarohem | N19: For 1nd: Kredba, Palyutin(10.2) After1st: Kredba, Palyutin(not suitable) Refused offer: Žižkovský | O19: 9 | P19: 9 | Q19: 1
A20: RPL | B20: Dobeš | C20: Prague HQ / BO | D20: 46035 | E20: =_xlfn.DAYS(TODAY(),D20) -> 50 | F20: 178528 | G20: 05_Car Purchase | H20: Mobile Buying | I20: Mobile Buying- Ostrava | J20: 25000+% | K20: Filip Lukašek | L20: Mirka | M20: AAA, práce.cz, jobs.cz, dobraprace, volnamista, jobdnes, pracezarohem | N20: After1st:Turay(not suitable) | O20: 1 | P20: 1 | Q20: 1
A21: RPL | B21: Zvěřinová | C21: Prague HQ / BO | D21: 46077 | E21: =_xlfn.DAYS(TODAY(),D21) -> 8 | F21: 178528 | G21: 05_Car Purchase | H21: Mobile Buying | I21: Mobile Buying Dispatcher Praha | J21: 25000+% | K21: Ondřej Holub | L21: Mirka | M21: AAA, práce.cz, jobs.cz, dobraprace, volnamista, jobdnes, pracezarohem | N21: Checking CVs/ new request | O21: 1 | P21: 1 | Q21: 1
C22: Mototechna
C23: Zličín
A24: NEW | B24: fill cap | C24: Zličín | D24: 46057 | E24: =_xlfn.DAYS(TODAY(),D24) -> 28 | G24: 04_Automotive OPS | H24: OPS (Part Time) | I24: Driver - Zličín | J24: 140 kč/Hod | K24: Jan Malchar | L24: Anna K. | M24: AAA | N24: Hired: Kočí (4.2), Blažka (4.2) For 2nd: Václavík (odloženo pro nemoc) | O24: 0.25 | P24: 0.25 | Q24: 3
B25: Reg. Praha | C25: Prague Branch
A26: RPL | B26: Dunda, Uher, fill cap | C26: Prague Branch | D26: 45919 | E26: =_xlfn.DAYS(TODAY(),D26) -> 166 | F26: 177091 178380 178368 180222 180494 | G26: 02_Car Sales | H26: Sales | I26: Salesman - Praha | J26: 25.000 + % | K26: Alen Svoboda | L26: Ondra | M26: AAA, práce, inwork | N26: For 2nd 2x Hired 16.2. Drahokoupil, 19.2. Humeník 2.3. Kótai Hired 12.1. Kamršek Hired for assistant 8.2. Dlabal Refused offer Kohák, Andrle No after 2nd 19x | O26: 36 | P26: 32 | Q26: 4
A27: RPL | B27: Král Josef | C27: Prague Branch | D27: 46008 | E27: =_xlfn.DAYS(TODAY(),D27) -> 77 | F27: 184212 | G27: 05_Car Purchase | H27: Buying | I27: Test driver - Praha | J27: 25 000 + 0 - 15 000 | K27: Petr Kuchynka | L27: Blanka | M27: AAA, prace.cz, pracezarohem, jobdnes | N27: Hiring Várady Hired Macháček (2.2.) No after 2nd Urban , Brož, Hubený Checking CV | O27: 20 | P27: 16 | Q27: 3
A28: RPL | C28: Prague Branch | D28: 46045 | E28: =_xlfn.DAYS(TODAY(),D28) -> 40 | G28: 05_Car Purchase | H28: Pricing CZ/SK/PL | I28: Pricing Expert | J28: 30 000 + 15 000 | K28: Jiří Somol | L28: Anna K. | M28: AAA, práce, inwork | N28: For1st: Hejduk (4.3) for 2nd int.: Kunst (25.2.) No: Dědek, Soustružník, Hlaváčková, Sivák, Bača | O28: 36.5 | P28: 33 | Q28: 1
A29: RPL | B29: Šimonová | C29: Prague Branch | D29: 46059 | E29: =_xlfn.DAYS(TODAY(),D29) -> 26 | G29: 05_Car Purchase | H29: Buying | I29: Receptionist | J29: 25 000 + 10 000 | K29: Petr Kuchynka | L29: Blanka | M29: AAA, prace.cz, pracezarohem, jobdnes | N29: Hiring Lisová (9.3.) Checking CVs | O29: 2 | P29: 2 | Q29: 1
A30: RPL | B30: Tomáš Kaiser | C30: Prague Branch | D30: 46054 | E30: =_xlfn.DAYS(TODAY(),D30) -> 31 | G30: 04_Automotive OPS | H30: OPS (Full Time) | I30: Helper - Praha | J30: 28 000 + 0 - 8 000 | K30: Jan Malchar | L30: Anna K. | M30: AAA, práce, inwork | N30: Roubal 1.2. No after 2nd: Slavík Švankmajer, Svoboda, Shten, Kalinov | O30: 26 | P30: 23 | Q30: 3
A31: RPL | B31: Jan Szabó | C31: Prague Branch | D31: 46062 | E31: =_xlfn.DAYS(TODAY(),D31) -> 23 | G31: 04_Automotive OPS | H31: OPS (Full Time) | I31: Helper Boxy a Sonax - Praha | J31: 28 000 + 0 - 8 000 | K31: Jan Malchar | L31: Anna K. | M31: AAA, práce, inwork | N31: Hired: Hangurbadžo (9.2.) Didnt come to the int: Peteřík 22.1., Vokulič (22.1) | O31: 4 | P31: 3 | Q31: 1
B32: Reg. Praha | C32: Čestlice
A33: RPL | B33: Šoltys | C33: Čestlice | D33: 45908 | E33: =_xlfn.DAYS(TODAY(),D33) -> 177 | F33: 176741 | G33: 02_Car Sales | H33: Selling | I33: Salesman - Čestlice | J33: 25.000 + 0 - 25.000 | K33: Alen Svoboda | L33: Ondra | M33: AAA, práce.cz, inwork, dobraprace | N33: Hired 2.3. Radčuk On hold Mládek Stopped hiring Reppenberger Checking CVs | O33: 4 | P33: 4 | Q33: 1
A34: RPL | B34: Hořínek | C34: Čestlice | D34: 46079 | E34: =_xlfn.DAYS(TODAY(),D34) -> 6 | F34: 179002 | G34: 05_Car Purchase | H34: Buying | I34: Test driver - Čestlice | J34: 25 000 + 0 - 15 000 | K34: Lukáš Geršic | L34: Kamila | M34: AAA, prace.cz, pracezarohem | N34: checking CVs | O34: 4 | P34: 4 | Q34: 1
A35: RPL | B35: Kilián | C35: Příbram | D35: 45971 | E35: =_xlfn.DAYS(TODAY(),D35) -> 114 | F35: 179002 | G35: 05_Car Purchase | H35: Buying | I35: Car Trader - Příbram | J35: 28 000 + 0 - 22 000 | K35: Lukáš Geršic | L35: Kamila | M35: AAA, prace.cz, pracezarohem | N35: In process: ex empl., To 2nd: Strama, Hochmann (waiting for term), No after 2nd: Říha, Niebauer, refused offer: Obdrdal, Vybíral 1x IM (F.Hořínek ze Sokolova) | O35: 2 | P35: 0 | Q35: 2
A36: RPL | B36: fill cap | C36: Čestlice | D36: 46055 | E36: =_xlfn.DAYS(TODAY(),D36) -> 30 | F36: DPP 2x | G36: 04_Automotive OPS | H36: OPS (Part Time) | I36: Driver - Čestlice | J36: 140 kč/Hod | K36: Jan Malchar | L36: Anna K. | M36: AAA, práce.cz, inwork, dobraprace | N36: Hired Hora (2.2.) No resp.: Čech, Kameník Vrbovec (17.10.), | O36: 0.25 | P36: 0.25 | Q36: 3
B37: Reg. Praha | C37: Klecany
J38: BRANCHES
B39: Bohemia 1 | C39: České Budějovice
A40: RPL | B40: fill cap | C40: České Budějovice | D40: 46028 | E40: =_xlfn.DAYS(TODAY(),D40) -> 57 | F40: 176834 | G40: 02_Car Sales | H40: Selling | I40: Salesman - České Budějovice 2 | J40: 25 000 + % | K40: Miroslav Varmuža | L40: Blanka | M40: AAA, práce, pracezarohem | N40: Hiring Vašák (2.3.) Hired Smutný (2.2.), Malý (16.2.) For 2nd Malý, Tyšler (next week) After 2nd Mužík, Volovenko Checking CV | O40: 8 | P40: 8 | Q40: 2
...

Sheet Summary
A1: AAA AUTO — VACANCY SUMMARY REPORT
A2: CZ | Active Vacancies Overview
A4: KEY METRICS
A5: TOTAL POSITIONS | B5: =COUNTIF(VACANCIES!Q:Q,">0") -> 65
A7: TOTAL VACANCIES | B7: =SUMIFS(tblVacancies[VAC], tblVacancies[Division], "<>") -> 102
A9: TOTAL VACANCIES RPL | B9: =SUMIF(VACANCIES!A:A,"RPL*",VACANCIES!Q:Q) -> 91
A11: TOTAL VACANCIES NEW | B11: =SUMIF(VACANCIES!A:A,"NEW*",VACANCIES!Q:Q) -> 11
A13: Vac by Division | B13: Vacancies
A14: 02_Car Sales | B14: 20
A15: 03_Financial Services | B15: 8
A16: 04_Automotive OPS | B16: 38
A17: 05_Car Purchase | B17: 14
A18: 06_HR | B18: 0
A19: 07_Stock & Logistics | B19: 9
A20: 08_Service | B20: 5
A21: 11_Call Centre | B21: 5
A22: 12_IT | B22: 0
A23: 16_Mototechna | B23: 0
A24: 21_Commerce | B24: 0
A25: (prázdné)
A26: 22_Cost Control & Back Office | B26: 1
A27: 10_Office Operations | B27: 2
A28: 09_Economic | B28: 0
A29: 01_Marketing & Communication | B29: 0
A30: 18_Data Science | B30: 0
A31: 20_Innovations | B31: 0
A32: Celkový součet | B32: 102
A35: Vac by branch | B35: Vacancies
A36: Prague Branch | B36: 13
A37: Ostrava | B37: 10
A38: Brno | B38: 8
A39: Liberec | B39: 6
A40: Teplice | B40: 6
A41: České Budějovice | B41: 6
A42: Čestlice | B42: 5
A43: Sokolov | B43: 4
A44: Kladno | B44: 3
A45: Chomutov | B45: 3
A46: Otrokovice | B46: 3
A47: Kolín | B47: 2
...

Sheet Zdroj číselníků
A2: Anna K. | C2: RPL | E2: 01_Marketing & Communication
A3: Blanka | C3: NEW | E3: 02_Car Sales
A4: Honza | E4: 03_Financial Services
A5: Kája | E5: 04_Automotive OPS
A6: Kamila | E6: 05_Car Purchase
A7: Mirka | E7: 06_HR
A8: Ondra | E8: 07_Stock & Logistics
A9: Vlaďka | E9: 08_Service
E10: 09_Economic
E11: 10_Office Operations
E12: 11_Call Centre
E13: 12_IT
E14: 16_Mototechna
E15: 18_Data Science
E16: 20_Innovations
E17: 21_Commerce
E34: 22_Cost Control & Back Office
